<?xml version='1.0'?>
    <sdf version='1.4'>
      
      <model name="target_model">
        
        <static>false</static>
        
        
        <link name='chassis'>
          <pose>0 0 .1 0 0 0</pose>
          
          <collision name='collision'>
            <geometry>
              <box>
                <size>.4 .2 .05</size>
              </box>
            </geometry>
          </collision>

          <visual name='visual'>
            <geometry>
              <box>
                <size>.4 .2 .05</size>
              </box>
            </geometry>
            
            <material>
							<ambient>1 0 0 1</ambient>
							<diffuse>1 0 0 1</diffuse>
							<specular>0.1 0.1 0.1 1</specular>
							<emissive>0 0 0 0</emissive>
						</material>
					
          </visual>

          <collision name='caster_collision'>
            <pose>-0.15 0 -0.05 0 0 0</pose>
            <geometry>
              <sphere>
              <radius>.05</radius>
            </sphere>
          </geometry>

          <surface>
            <friction>
              <ode>
                <mu>0</mu>
                <mu2>0</mu2>
                <slip1>1.0</slip1>
                <slip2>1.0</slip2>
              </ode>
            </friction>
          </surface>
        </collision>

        <visual name='caster_visual'>
          <pose>-0.15 0 -0.05 0 0 0</pose>
          <geometry>
            <sphere>
              <radius>.05</radius>
            </sphere>
          </geometry>
          
          <material>
						<ambient>1 0 0 1</ambient>
						<diffuse>1 0 0 1</diffuse>
						<specular>0.1 0.1 0.1 1</specular>
						<emissive>0 0 0 0</emissive>
					</material>
					
        </visual>
      </link>
      
      
      <link name="left_wheel">
        <pose>0.1 0.13 0.1 0 1.5707 1.5707</pose>
        
        <collision name="collision">
          <geometry>
            <cylinder>
              <radius>.1</radius>
              <length>.05</length>
            </cylinder>
          </geometry>
        </collision>
        
        
        <visual name="visual">
          <geometry>
            <cylinder>
              <radius>.1</radius>
              <length>.05</length>
            </cylinder>
          </geometry>
          
          <material>
						<ambient>1 0 0 1</ambient>
						<diffuse>1 0 0 1</diffuse>
						<specular>0.1 0.1 0.1 1</specular>
						<emissive>0 0 0 0</emissive>
					</material>
					
        </visual>
      
      </link>

      
      
      <link name="right_wheel">
        <pose>0.1 -0.13 0.1 0 1.5707 1.5707</pose>
        
        <collision name="collision">
          <geometry>
            <cylinder>
              <radius>.1</radius>
              <length>.05</length>
            </cylinder>
          </geometry>
        </collision>
        
        
        <visual name="visual">
          <geometry>
            <cylinder>
              <radius>.1</radius>
              <length>.05</length>
            </cylinder>
          </geometry>
          <material>
						<ambient>1 0 0 1</ambient>
						<diffuse>1 0 0 1</diffuse>
						<specular>0.1 0.1 0.1 1</specular>
						<emissive>0 0 0 0</emissive>
					</material>
        </visual>
      
      </link>
      
      
      
      <joint type="revolute" name="left_wheel_hinge">
        <pose>0 0 -0.03 0 0 0</pose>
        <child>left_wheel</child>
        <parent>chassis</parent>
        <axis>
          <xyz>0 1 0</xyz>
        </axis>
      </joint>

      
      
      
      <joint type="revolute" name="right_wheel_hinge">
        <pose>0 0 0.03 0 0 0</pose>
        <child>right_wheel</child>
        <parent>chassis</parent>
        <axis>
          <xyz>0 1 0</xyz>
        </axis>
      </joint>
      
      <!--
      <transmission name="right_trans">
		<type>transmission_interface/SimpleTransmission</type>
		
		<joint name="right_wheel_hinge">
		<hardwareInterface>EffortJointInterface</hardwareInterface>
		</joint>

		<actuator name="rightMotor">
		<hardwareInterface>EffortJointInterface</hardwareInterface>
		<mechanicalReduction>10</mechanicalReduction>
		</actuator>

	  </transmission>
      
      <transmission name="left_trans">
		<type>transmission_interface/SimpleTransmission</type>
		
		<joint name="left_wheel_hinge">
		<hardwareInterface>EffortJointInterface</hardwareInterface>
		</joint>

		<actuator name="leftMotor">
		<hardwareInterface>EffortJointInterface</hardwareInterface>
		<mechanicalReduction>10</mechanicalReduction>
		</actuator>

	  </transmission>
	  -->
	
	<!--
	<plugin name="differential_drive_controller" filename="libgazebo_ros_diff_drive.so">
		<alwaysOn>true</alwaysOn>
		<updateRate>100</updateRate>
		<leftJoint>left_wheel_hinge</leftJoint>
		<rightJoint>right_wheel_hinge</rightJoint>
		<wheelSeparation>${chassisWidth+wheelWidth}</wheelSeparation>
		<wheelDiameter>${2*wheelRadius}</wheelDiameter>
		<torque>20</torque>
		<commandTopic>mybot/cmd_vel</commandTopic>
		<odometryTopic>mybot/odom_diffdrive</odometryTopic>
		<odometryFrame>odom</odometryFrame>
		<robotBaseFrame>footprint</robotBaseFrame>
	</plugin>  
	-->  
	<plugin name="differential_drive_controller" filename="libgazebo_ros_diff_drive.so">
		<alwaysOn>true</alwaysOn>
		<updateRate>50</updateRate>
		<leftJoint>left_wheel_hinge</leftJoint>
		<rightJoint>right_wheel_hinge</rightJoint>
		<wheelSeparation>0.26</wheelSeparation>
		<wheelDiameter>0.2</wheelDiameter>
		<torque>20</torque>
		<commandTopic>/target_model/cmd_vel</commandTopic>
		<odometryTopic>/target_model/odom_diffdrive</odometryTopic>
		<odometryFrame>target_odom</odometryFrame>
		<robotBaseFrame>base_footprint</robotBaseFrame>
	</plugin>  

	  
      </model>
    
    
    </sdf>
